Workbook

Sheet 版本說明
A1: Defense v1 / v2 / v3 與實驗分類（QUAN-1107 / QUAN-1108）
A2: 整理日 2026-10-12。數字來源寫在每張表下方；同一張表內的數字口徑相同，不同表之間不可直接比較。
A4: 1. 共同邏輯（三版都一樣）
A5: 池子：ETH/USDC，谷型 LP（inverted gaussian），中心 ±20%，16 段。
A6: 訊號：Binance ETHUSDT 日收盤，EMA 90/100/110/120 四個虛擬帳戶，各自撤出與分 4 階段回補；部署比例 F = 四帳戶平均。
A7: ETH 比例 s：收盤 > EMA100 時 70%，否則 50%。跌破下緣（−20%）撤出，突破上緣（+20%）重建。
A8: 三版的差別只在下表的增改規則，所以屬於同一類策略。
A10: 2. 版本差異
A11: 版本 | B11: 相對前一版的改動 | C11: 規格書 | D11: 程式 | E11: 程式位置 | H11: 備註
A12: v1 | B12: 規格書基準版。8+8 段、每段價格等寬 2.5%、規格書權重、swap 成本平價 0.1%。 | C12: USDC/ETH gamma maker defence v1（Google Sheet） | D12: gamma_maker_defense_ethusdc_v1.py | E12: maker-defense | H12: 我們的實驗基準（SPEC=v1），自 EXP-156 起
A13: v2 | B13: 回補階梯改為 +7.5 / 12.5 / 17.5 / 22.5%；F 改用虛擬 LP 價值比例；新增複利模式（每月 1 日把手續費加回 LP）。 | C13: ETH-USDC MGL 規格書 v2 | D13: gamma_maker_defense_ethusdc_v2.py | E13: maker-defense（ca675a1, 10-06） | H13: 程式預設改為池費 0.05% + 深度滑價
A14: v3 | B14: v2 再加「均線乖離規則」：收盤 ≥ EMA100 × 1.40 時 LP 全部撤成 USDC；乖離縮回 +20% 以下才恢復一般規則。 | C14: ETH-USDC Maker-Grade Liquidity 規格書 v3（新增均線乖離規則），Slack 10-06 | D14: gamma_maker_defense_ethusdc_v3.py | E14: 只在 Slack（10-12），尚未進 git | H14: ETH-cbBTC 不導入乖離規則（規格書第 0 節）
A16: 3. 逐年績效（每年 1/2 以 $100k 起算，各年不連續）
A17: 系列 | B17: 2022 | C17: 2023 | D17: 2024 | E17: 2025 | F17: 四年平均 | H17: 口徑
A18: v1 程式（規格書設定） | B18: 0.118 | C18: 0.404 | D18: 0.323 | E18: 0.163 | F18: =AVERAGE(B18:E18) | H18: swap 平價 0.1%；Maker，Slack 2026-10-06
A19: v2 程式，標準模式 | B19: 0.207 | C19: 0.219 | D19: 0.195 | E19: 0.226 | F19: =AVERAGE(B19:E19) | H19: 池費 0.05% + 深度滑價；GAMMA_MAKER_DEFENSE_ETHUSDC_V2.md 6.0
A20: v2 規格書，標準模式 | B20: 0.151 | C20: 0.231 | D20: 0.252 | E20: 0.287 | F20: =AVERAGE(B20:E20) | H20: 規格書獎勵模型（年底資產 115.1 / 123.1 / 125.2 / 128.7 $k）
A21: v3 沒有逐年數字：規格書只給 2021-05-05..2026-08-31 連續期（見第 4 節），程式結果尚未公布。
A23: 4. 連續期績效
A24: 系列 | B24: 期間 | C24: 期末資產（$k，起始 100） | D24: 總報酬 | E24: 最大回撤 | H24: 口徑
A25: v1 Google Sheet | B25: 2022-01-02..2025-12-31 | C25: 183.5 | D25: =C25/100-1 | E25: -0.258 | H25: APR 16.4%；Maker 回測，swap 0.1%、池費 0.05%
A26: v1 我們重現（EXP-156 的 A） | B26: 2022-01-02..2025-12-31 | C26: 184 | D26: =C26/100-1 | H26: CAGR 16.5%；v6_validate.py SPEC=v1
A27: v2 規格書，標準 | B27: 2021-05-05..2026-08-31 | C27: 186.2 | D27: =C27/100-1 | E27: -0.28 | H27: 規格書 v3 第 7 節，UTC 0 時判定
A28: v3 規格書，標準 | B28: 2021-05-05..2026-08-31 | C28: 231.9 | D28: =C28/100-1 | E28: -0.19 | H28: 原資 125.4 + 已領獎勵 106.5
A29: v2 規格書，複利 | B29: 2021-05-05..2026-08-31 | C29: 262.5 | D29: =C29/100-1 | E29: -0.36 | H29: 規格書 v3 第 7 節
A30: v3 規格書，複利 | B30: 2021-05-05..2026-08-31 | C30: 323.7 | D30: =C30/100-1 | E30: -0.24 | H30: 規格書 v3 第 7 節
A31: v2 規格書，24 種判定時間平均 | B31: 2021-05-05..2026-08-31 | C31: 142.8 | D31: =C31/100-1 | E31: -0.38 | H31: 判定時間偏移 UTC 0..23 時的平均
A32: v3 規格書，24 種判定時間平均 | B32: 2021-05-05..2026-08-31 | C32: 193.4 | D32: =C32/100-1 | E32: -0.23 | H32: 實際運作應預期接近此值（規格書）
A33: ETH 持有 | B33: 2021-05-05..2026-08-31 | C33: 70 | D33: =C33/100-1 | E33: -0.79 | H33: 規格書 v3 第 7 節
A34: 規格書數字來自作者的獎勵模型，不是 Demeter 分鐘資料回測；v2 程式與規格書逐年差 −6.1..+5.6 $k，主要差在手續費模型。
A36: 5. 我們的最佳候選 vs v1：EXP-157（v6.75，回補日當天不能創盤中新低），全歷史 7 池
A37: 池子 | B37: 起日 | C37: v1 CAGR | D37: EXP-157 CAGR | E37: v1 最大回撤 | F37: EXP-157 最大回撤 | G37: CAGR 差 | H37: 結果
A38: ETH 主網 0.05% 0x88e6 | B38: 2021-05-06 | C38: 0.1355 | D38: 0.1509 | E38: -0.229 | F38: -0.235 | G38: =D38-C38 | H38: 贏
A39: ETH 主網 0.3% 0x8ad5 | B39: 2021-05-06 | C39: 0.1378 | D39: 0.1586 | E39: -0.21 | F39: -0.217 | G39: =D39-C39 | H39: 贏
A40: ETH Base 0.05% 0xd0b5 | B40: 2023-12-01 | C40: 0.1696 | D40: 0.1692 | E40: -0.347 | F40: -0.359 | G40: =D40-C40 | H40: 輸（Calmar）
A41: ETH Arbitrum 0.05% 0xc696 | B41: 2023-06-09 | C41: 0.2688 | D41: 0.2656 | E41: -0.314 | F41: -0.325 | G41: =D41-C41 | H41: 輸（Calmar）
A42: ETH Base 0.3% 0x6c56 | B42: 2025-01-01 | C42: 0.1648 | D42: 0.1704 | E42: -0.246 | F42: -0.246 | G42: =D42-C42 | H42: 贏
A43: BTC 主網 WBTC 0.3% 0x99ac | B43: 2021-11-02 | C43: 0.1043 | D43: 0.1049 | E43: -0.301 | F43: -0.302 | G43: =D43-C43 | H43: 贏（雜訊內）
A44: BTC Base cbBTC 0.05% 0xfbb6 | B44: 2024-10-01 | C44: 0.2046 | D44: 0.2052 | E44: -0.167 | F44: -0.167 | G44: =D44-C44 | H44: 贏（雜訊內）
A45: 贏的池數 | G45: =COUNTIF(H38:H44,"贏*") | H45: 7 池中
...

Sheet 訊號線
A1: EXP | B1: 版本 | C1: 狀態 | D1: 通過 | E1: 判定規則 | F1: 含 v6.75 | G1: 說明（中文） | H1: 原始名稱（registry） | I1: 開發期中位數增益（pt） | J1: 開發期勝 | K1: holdout / 全歷史結果 | L1: ETH 連續 CAGR | M1: ETH 連續最大回撤 | N1: Jira | O1: 文件
A2: EXP-024 | B2: v6.19 | C2: 開發期淘汰 | D2: 否 | E2: dev + holdout | F2: 否 | G2: 趨勢線改用 n 日 Donchian 通道中線 | H2: regime line = midpoint of the n-day Donchian channel instead of EMA(n) (v6.19) | I2: -1.44 | J2: 2/5 | L2: 0.15 | M2: -0.204 | N2: QUAN-876 | O2: EXP-024-donchian-regime.md
A3: EXP-025 | B3: v6.20 | C3: 開發期淘汰 | D3: 否 | E3: dev + holdout | F3: 否 | G3: 趨勢線改用 Hull MA(n) | H3: regime line = Hull MA(n) instead of EMA(n) (v6.20) | I3: -10.53 | J3: 0/5 | L3: 0.032 | M3: -0.241 | N3: QUAN-877 | O3: EXP-025-hma-regime.md
A4: EXP-026 | B4: v6.21 | C4: 開發期淘汰 | D4: 否 | E4: dev + holdout | F4: 否 | G4: 趨勢判斷改用 n 日報酬 > 0（時間序列動能） | H4: regime = n-day return > 0 (time-series momentum) instead of price above EMA(n) (v6.21) | I4: -7.42 | J4: 1/5 | L4: 0.04 | M4: -0.326 | N4: QUAN-878 | O4: EXP-026-roc-regime.md
A5: EXP-027 | B5: v6.22 | C5: 開發期淘汰 | D5: 否 | E5: dev + holdout | F5: 否 | G5: 趨勢線改用 Supertrend（ATR(n) × 3） | H5: regime line = Supertrend (ATR(n) × 3 trailing band) instead of EMA(n) (v6.22) | I5: -15.8 | J5: 0/5 | L5: -0.035 | M5: -0.352 | N5: QUAN-879 | O5: EXP-027-supertrend-regime.md
A6: EXP-031 | B6: v6.26 | C6: 開發期淘汰 | D6: 否 | E6: dev + holdout | F6: 否 | G6: 帳戶只在收盤同時高於 EMA(n) 與 Donchian 中線時武裝 | H6: account armed only while the close is above both EMA(n) and the Donchian midpoint(n) (v6.26) | I6: 0.12 | J6: 3/5 | L6: 0.142 | M6: -0.209 | N6: QUAN-883 | O6: EXP-031-consensus-ema-donchian.md
A7: EXP-032 | B7: v6.19 | C7: 通過（holdout） | D7: 是 | E7: dev + holdout | F7: 否 | G7: Donchian 中線版本（v6.19）單獨判定 | H7: Donchian-midpoint regime line (v6.19) judged standalone (v6.19r) | I7: -1.44 | J7: 2/5 | K7: 2/3 pools | L7: 0.15 | M7: -0.204 | N7: QUAN-884 | O7: EXP-032-donchian-regime-standalone.md
A8: EXP-033 | B8: v6.23 | C8: holdout 失敗 | D8: 否 | E8: dev + holdout | F8: 否 | G8: EMA + Donchian 合成（v6.23）單獨判定 | H8: EMA + Donchian ensemble (v6.23) judged standalone (v6.23r) | I8: 4.53 | J8: 3/5 | K8: 1/3 pools | L8: 0.157 | M8: -0.215 | N8: QUAN-885 | O8: EXP-033-ensemble-standalone.md
A9: EXP-035 | B9: v6.26 | C9: holdout 失敗 | D9: 否 | E9: dev + holdout | F9: 否 | G9: EMA / Donchian 共識（v6.26）單獨判定 | H9: EMA/Donchian consensus regime (v6.26) judged standalone (v6.26r) | I9: 0.12 | J9: 3/5 | K9: 1/3 pools | L9: 0.142 | M9: -0.209 | N9: QUAN-887 | O9: EXP-035-consensus-standalone.md
A10: EXP-036 | B10: v6.27 | C10: 開發期淘汰 | D10: 否 | E10: dev + holdout | F10: 否 | G10: 趨勢線改用 SMA(n)，n = 170/190/210/230 | H10: regime line = SMA(n), n = 170/190/210/230 (the classic 200-day family) (v6.27) | I10: -8.74 | J10: 0/5 | L10: 0.018 | M10: -0.329 | N10: QUAN-888 | O10: EXP-036-sma-regime.md
A11: EXP-037 | B11: v6.28 | C11: 開發期淘汰 | D11: 否 | E11: dev + holdout | F11: 否 | G11: 趨勢線改用 Ichimoku 雲頂 | H11: regime line = top of the Ichimoku cloud, standard periods scaled 1x..2.5x (v6.28) | I11: -6.12 | J11: 0/5 | L11: 0.071 | M11: -0.284 | N11: QUAN-889 | O11: EXP-037-ichimoku-regime.md
A12: EXP-038 | B12: v6.29 | C12: 開發期淘汰 | D12: 否 | E12: dev + holdout | F12: 否 | G12: 趨勢判斷改用 Aroon Up(n) > Aroon Down(n) | H12: regime = Aroon Up(n) > Aroon Down(n), n = 90/100/110/120 (v6.29) | I12: -10.31 | J12: 2/5 | L12: 0.021 | M12: -0.376 | N12: QUAN-890 | O12: EXP-038-aroon-regime.md
A13: EXP-039 | B13: v6.30 | C13: 開發期淘汰 | D13: 否 | E13: dev + holdout | F13: 否 | G13: 趨勢判斷改用收盤價在 n 日高點 20% 以內 | H13: regime = close within 20% of its n-day high, n = 90/100/110/120 (v6.30) | I13: -6.19 | J13: 2/5 | L13: 0.105 | M13: -0.279 | N13: QUAN-891 | O13: EXP-039-drawdown-regime.md
A14: EXP-040 | B14: v6.29 | C14: holdout 失敗 | D14: 否 | E14: dev + holdout | F14: 否 | G14: Aroon 版本單獨判定為 BTC 池策略 | H14: Aroon regime (v6.29) judged standalone as a BTC-pool strategy (v6.29r) | I14: -10.31 | J14: 2/5 | K14: 0/2 windows | L14: 0.021 | M14: -0.376 | N14: QUAN-892 | O14: EXP-040-aroon-btc-standalone.md
A15: EXP-041 | B15: v6.28 | C15: holdout 失敗 | D15: 否 | E15: dev + holdout | F15: 否 | G15: Ichimoku 版本單獨判定為 BTC 池策略 | H15: Ichimoku-cloud regime (v6.28) judged standalone as a BTC-pool strategy (v6.28r) | I15: -6.12 | J15: 0/5 | K15: 0/2 windows | L15: 0.071 | M15: -0.284 | N15: QUAN-893 | O15: EXP-041-ichimoku-btc-standalone.md
A16: EXP-042 | B16: v6.27 | C16: holdout 失敗 | D16: 否 | E16: dev + holdout | F16: 否 | G16: SMA200 系列單獨判定為 BTC 池策略 | H16: SMA(200 family) regime (v6.27) judged standalone as a BTC-pool strategy (v6.27r) | I16: -8.74 | J16: 0/5 | K16: 0/2 windows | L16: 0.018 | M16: -0.329 | N16: QUAN-894 | O16: EXP-042-sma-btc-standalone.md
A17: EXP-043 | B17: v6.21 | C17: holdout 失敗 | D17: 否 | E17: dev + holdout | F17: 否 | G17: 時間序列動能單獨判定為 BTC 池策略 | H17: time-series-momentum regime (v6.21) judged standalone as a BTC-pool strategy (v6.21r) | I17: -7.42 | J17: 1/5 | K17: 0/2 windows | L17: 0.04 | M17: -0.326 | N17: QUAN-895 | O17: EXP-043-roc-btc-standalone.md
A18: EXP-050 | B18: v6.37 | C18: 開發期淘汰 | D18: 否 | E18: dev + holdout | F18: 否 | G18: ETH 50% + EMA / Donchian 共識 | H18: ETH share 50% + EMA/Donchian consensus regime (v6.37) | I18: -3.18 | J18: 1/5 | L18: 0.134 | M18: -0.177 | N18: QUAN-902 | O18: EXP-050-share50-consensus.md
A20: 訊號線：把 EMA 換成別的趨勢線（Donchian、SMA、Aroon、Ichimoku…）
A21: 結論：EMA 換成別的趨勢線都沒贏；Donchian 只在單獨等級通過
A22: 綠底 = 通過。ETH 連續 CAGR / 回撤是 registry 記錄的 ETH 連續回測；全歷史判定的逐池數字見各 EXP 文件。

Sheet F引擎
A1: EXP | B1: 版本 | C1: 狀態 | D1: 通過 | E1: 判定規則 | F1: 含 v6.75 | G1: 說明（中文） | H1: 原始名稱（registry） | I1: 開發期中位數增益（pt） | J1: 開發期勝 | K1: holdout / 全歷史結果 | L1: ETH 連續 CAGR | M1: ETH 連續最大回撤 | N1: Jira | O1: 文件
A2: EXP-012 | B2: v6.9 | C2: 開發期淘汰 | D2: 否 | E2: dev + holdout | F2: 否 | G2: 手續費 vs LVR 閘門：7 日每單位流動性手續費 < LVR 時 F = 0 | H2: fee-vs-LVR gate: F = 0 while 7-day pool fees per unit liquidity < LVR (v6.9) | I2: -2.18 | J2: 0/5 | L2: 0.064 | M2: -0.254 | N2: QUAN-856 | O2: EXP-012-fee-lvr-gate.md
A3: EXP-022 | B3: v6.17 | C3: 開發期淘汰 | D3: 否 | E3: dev + holdout | F3: 否 | G3: LP 手續費再投入梯子（複利），不領出 | H3: LP fees redeployed into the ladder instead of paid out (v6.17) | I3: 0.46 | J3: 3/5 | L3: 0.199 | M3: -0.325 | N3: QUAN-873 | O3: EXP-022-fee-compounding.md
A4: EXP-028 | B4: v6.23 | C4: 開發期淘汰 | D4: 否 | E4: dev + holdout | F4: 否 | G4: F = 8 個帳戶平均（4 個 EMA、4 個 Donchian 中線） | H4: F = mean of 8 accounts (4 on EMA(n), 4 on the Donchian midpoint(n)) (v6.23) | I4: 4.53 | J4: 3/5 | L4: 0.157 | M4: -0.215 | N4: QUAN-880 | O4: EXP-028-ensemble-ema-donchian.md
A5: EXP-045 | B5: v6.32 | C5: 開發期淘汰 | D5: 否 | E5: dev + holdout | F5: 否 | G5: F 每週讀一次（用週日的值） | H5: signal engine's F read once a week (Sunday value held) (v6.32) | I5: 0.24 | J5: 3/5 | L5: 0.106 | M5: -0.251 | N5: QUAN-897 | O5: EXP-045-weekly-f.md
A6: EXP-047 | B6: v6.34 | C6: 開發期淘汰 | D6: 否 | E6: dev + holdout | F6: 否 | G6: F 不低於 25%（永遠保留一個回補階段） | H6: F never below 25% (one refill stage always deployed) (v6.34) | I6: -4.99 | J6: 1/5 | L6: 0.096 | M6: -0.228 | N6: QUAN-899 | O6: EXP-047-f-floor.md
A7: EXP-053 | B7: v6.40 | C7: 開發期淘汰 | D7: 否 | E7: dev + holdout | F7: 否 | G7: 收盤在100日均線下時，近14天波動越大就把部署比例縮得越小 | H7: downside volatility targeting: F x min(1, sigma*/sigma_14) while close <= EMA100 (v6.40) | I7: -0.77 | J7: 1/5 | L7: 0.123 | M7: -0.23 | N7: QUAN-934 | O7: EXP-053-down-vol-target.md
A8: EXP-054 | B8: v6.41 | C8: 開發期淘汰 | D8: 否 | E8: dev + holdout | F8: 否 | G8: 近30天走勢太盤整（漲跌來回、沒有方向）時，跌破均線先不出場 | H8: EMA exit only while the 30-day efficiency ratio >= 1/sqrt(30) (chop gate) (v6.41) | I8: -9.6 | J8: 0/5 | L8: 0.066 | M8: -0.279 | N8: QUAN-935 | O8: EXP-054-er-chop-gate.md
A9: EXP-064 | B9: v6.51 | C9: 開發期淘汰 | D9: 否 | E9: dev + holdout | F9: 否 | G9: 淨值從歷史高點回落時按比例縮小部署比例，回落20%就全部撤出 | H9: CPPI floor: F x clip((W/HWM - 0.8)/0.2) on the strategy's own net value (v6.51) | I9: -1.67 | J9: 2/5 | L9: 0.084 | M9: -0.182 | N9: QUAN-946 | O9: EXP-064-cppi-floor.md
A10: EXP-067 | B10: v6.54 | C10: 開發期淘汰 | D10: 否 | E10: dev + holdout | F10: 否 | G10: 只有站回均線上方時才分段補倉，看跌破後就開始補倉是否真的需要 | H10: staged refill only while the account is above its EMA (ablation) (v6.54) | I10: -18.98 | J10: 0/5 | L10: 0.021 | M10: -0.268 | N10: QUAN-949 | O10: EXP-067-refill-armed-only.md
A11: EXP-068 | B11: v6.55 | C11: 開發期淘汰 | D11: 否 | E11: dev + holdout | F11: 否 | G11: 站回均線那天直接全額部署，拿掉分段補倉看它是否真的需要 | H11: full deployment at the EMA re-arm instead of the staged refill (ablation) (v6.55) | I11: -17.11 | J11: 1/5 | L11: 0.025 | M11: -0.319 | N11: QUAN-950 | O11: EXP-068-rearm-full.md
A12: EXP-069 | B12: v6.56 | C12: 開發期淘汰 | D12: 否 | E12: dev + holdout | F12: 否 | G12: 拿掉「價格漲到中心價1.2倍就重新置中」這條規則，看它是否真的需要 | H12: signal engine without the accounts' upper rebuild (ablation) (v6.56) | I12: 0 | J12: 0/5 | L12: 0.14 | M12: -0.228 | N12: QUAN-952 | O12: EXP-069-no-upper-rebuild.md
A13: EXP-076 | B13: v6.63 | C13: 開發期淘汰 | D13: 否 | E13: dev + holdout | F13: 否 | G13: 只用一條100日均線決定部署比例，拿掉四條均線（90–120日）的組合 | H13: one EMA100 account instead of four (ensemble ablation) (v6.63) | I13: 0.8 | J13: 4/5 | L13: 0.134 | M13: -0.213 | N13: QUAN-959 | O13: EXP-076-single-account.md
... A22: EXP-105 | B22: v6.92 | C22: 開發期淘汰 | D22: 否 | E22: dev + holdout | F22: 否 | G22: 池內流動性擁擠（7日均值超過90日中位數1.5倍）時，部署比例上限50% | H22: F capped at 50% while pool liquidity is crowded (v6.92) | I22: -0.01 | J22: 2/5 | L22: 0.155 | M22: -0.17 | N22: QUAN-989 | O22: EXP-105-crowd-cap.md
A24: F 引擎：四帳戶怎麼算出部署比例 F、多久讀一次、下限
A25: 結論：全部失敗；四帳戶 EMA 引擎不要動
A26: 綠底 = 通過。ETH 連續 CAGR / 回撤是 registry 記錄的 ETH 連續回測；全歷史判定的逐池數字見各 EXP 文件。

Sheet 撤出停損
A1: EXP | B1: 版本 | C1: 狀態 | D1: 通過 | E1: 判定規則 | F1: 含 v6.75 | G1: 說明（中文） | H1: 原始名稱（registry） | I1: 開發期中位數增益（pt） | J1: 開發期勝 | K1: holdout / 全歷史結果 | L1: ETH 連續 CAGR | M1: ETH 連續最大回撤 | N1: Jira | O1: 文件
A2: EXP-016 | B2: v6.13 | C2: 開發期淘汰 | D2: 否 | E2: dev + holdout | F2: 否 | G2: 毒性暫停：5 分鐘內波動 1% 後撤梯子 30 分鐘 | H2: toxicity pause: pull the ladder 30 min after a 1% five-minute move (v6.13) | I2: -1.9 | J2: 2/5 | L2: 0.183 | M2: -0.281 | N2: QUAN-862 | O2: EXP-016-toxicity-pause.md
A3: EXP-017 | B3: v6.13r | C3: holdout 失敗 | D3: 否 | E3: dev + holdout | F3: 否 | G3: v6.13 毒性暫停改用 Calmar 規則在 Base 重新判定 | H3: v6.13 toxicity pause re-registered under a Calmar rule on the Base holdout (v6.13r) | I3: -1.9 | J3: 2/5 | K3: 1/3 | L3: 0.183 | M3: -0.281 | N3: QUAN-863 | O3: EXP-017-toxicity-pause-calmar.md
A4: EXP-044 | B4: v6.31 | C4: 通過（holdout） | D4: 是 | E4: dev + holdout | F4: 否 | G4: 連續兩天的每日檢查都在梯子外，才算出區間 | H4: range exit needs two consecutive daily checks outside the ladder (v6.31) | I4: -1.9 | J4: 2/5 | K4: 3/3 pools (standalone) | L4: 0.158 | M4: -0.198 | N4: QUAN-896 | O4: EXP-044-exit-confirm.md
A5: EXP-048 | B5: v6.35 | C5: 通過（holdout） | D5: 是 | E5: dev + holdout | F5: 否 | G5: ETH 50% + 兩天確認出區間 | H5: ETH share 50% + range exit needs two consecutive daily checks (v6.35) | I5: -4.14 | J5: 2/5 | K5: 3/3 pools (standalone) | L5: 0.153 | M5: -0.161 | N5: QUAN-900 | O5: EXP-048-share50-exit-confirm.md
A6: EXP-056 | B6: v6.43 | C6: 開發期淘汰 | D6: 否 | E6: dev + holdout | F6: 否 | G6: 檢查價格是否跑出區間改成每小時一次，而不是每天只檢查一次 | H6: range-exit check every hour instead of once a day (v6.43) | I6: -0.05 | J6: 2/5 | L6: 0.116 | M6: -0.233 | N6: QUAN-938 | O6: EXP-056-exit-check-hourly.md
A7: EXP-066 | B7: v6.53 | C7: holdout 失敗 | D7: 否 | E7: dev + holdout | F7: 否 | G7: 拿掉下方停損（跌破中心價8折就出場），看它是否真的需要 | H7: signal engine without the accounts' lower stop (ablation) (v6.53) | I7: 0.27 | J7: 3/5 | K7: 1/2 windows (time-split) | L7: 0.142 | M7: -0.224 | N7: QUAN-948 | O7: EXP-066-no-lower-stop.md
A8: EXP-095 | B8: v6.82 | C8: 開發期淘汰 | D8: 否 | E8: dev + holdout | F8: 否 | G8: 跌破均線時，要池子近3天成交量高於近30天常態才真的出場 | H8: EMA exit only on pool volume above normal (v6.82) | I8: -2.63 | J8: 0/5 | L8: 0.112 | M8: -0.231 | N8: QUAN-979 | O8: EXP-095-exit-vol-confirm.md
A9: EXP-097 | B9: v6.84 | C9: 開發期淘汰 | D9: 否 | E9: dev + holdout | F9: 否 | G9: 整天連盤中最高價都在均線下才出場，盤中曾站回均線就先不出場 | H9: EMA exit only on a full day below the EMA (v6.84) | I9: -0.45 | J9: 1/5 | L9: 0.078 | M9: -0.318 | N9: QUAN-981 | O9: EXP-097-exit-full-day.md
A10: EXP-101 | B10: v6.88 | C10: 開發期淘汰 | D10: 否 | E10: dev + holdout | F10: 否 | G10: 下方停損改看盤中最低價，盤中一跌破中心價8折就出場 | H10: lower stop on the intraday low (v6.88) | I10: 0 | J10: 0/5 | L10: 0.107 | M10: -0.243 | N10: QUAN-985 | O10: EXP-101-intraday-stop.md
A11: EXP-106 | B11: v6.93 | C11: 開發期淘汰 | D11: 否 | E11: dev + holdout | F11: 是 | G11: 創新低那天不補倉，且價格跑出區間要連續兩天才重新擺放 | H11: v6.75 plus two-day range-exit confirmation (v6.93) | I11: -2.42 | J11: 2/5 | L11: 0.172 | M11: -0.212 | N11: QUAN-990 | O11: EXP-106-nolow-exit-confirm.md
A12: EXP-161 | B12: v6.146 | C12: 失敗（全歷史） | D12: 否 | E12: 全歷史 | F12: 是 | G12: 創新低那天不補倉，且下方停損改看盤中最低價，盤中跌破8折就出場 | H12: v6.75 + intraday lower stop on every pool on spec v1 (v6.146) | K12: full-history 3/7 pools (ETH 1 of 5; BTC 2 of 2) | N12: QUAN-1048 | O12: EXP-161-nolow-istop-specv1.md
A13: EXP-162 | B13: v6.147 | C13: 失敗（全歷史） | D13: 否 | E13: 全歷史 | F13: 是 | G13: 創新低那天不補倉，且價格跑出區間要連續兩天才重新擺放（新基準 spec v1） | H13: v6.75 + two-day EMA exit confirmation on every pool on spec v1 (v6.147) | K13: full-history 1/7 pools (ETH 1 of 5; BTC 0 of 2) | N13: QUAN-1049 | O13: EXP-162-nolow-exit2-specv1.md
A15: 撤出 / 停損：什麼時候把 LP 撤回 USDC
A16: 結論：兩天確認單獨通過，全歷史只贏 1/7；盤中停損只對 WBTC 有用
A17: 綠底 = 通過。ETH 連續 CAGR / 回撤是 registry 記錄的 ETH 連續回測；全歷史判定的逐池數字見各 EXP 文件。

Sheet 回補
A1: EXP | B1: 版本 | C1: 狀態 | D1: 通過 | E1: 判定規則 | F1: 含 v6.75 | G1: 說明（中文） | H1: 原始名稱（registry） | I1: 開發期中位數增益（pt） | J1: 開發期勝 | K1: holdout / 全歷史結果 | L1: ETH 連續 CAGR | M1: ETH 連續最大回撤 | N1: Jira | O1: 文件
A2: EXP-005 | B2: v6.5 | C2: 開發期淘汰 | D2: 否 | E2: dev + holdout | F2: 否 | G2: 回補改用只放 USDC 的區間掛單，不用市價買 | H2: refills as quote-only range orders instead of market buys (v6.5) | I2: -2.34 | J2: 1/5 | L2: 0.051 | M2: -0.158 | N2: QUAN-839 | O2: EXP-005-refill-range-order.md
A3: EXP-082 | B3: v6.69 | C3: 開發期淘汰 | D3: 否 | E3: dev + holdout | F3: 否 | G3: 跌破均線出場後，DVOL近3天均值低於前3天均值才允許分段補倉 | H3: refill stages only while implied volatility (DVOL) is falling (v6.69) | I3: -0.37 | J3: 1/5 | L3: 0.139 | M3: -0.22 | N3: QUAN-966 | O3: EXP-082-dvol-falling-refill.md
A4: EXP-083 | B4: v6.70 | C4: 開發期淘汰 | D4: 否 | E4: dev + holdout | F4: 否 | G4: 資金費率7天均值為負時，補倉第一段不必等連續3天確認，反彈5%就直接放回 | H4: negative funding waives the 3-day hold of the first refill stage (v6.70) | I4: -0.25 | J4: 2/5 | L4: 0.117 | M4: -0.224 | N4: QUAN-967 | O4: EXP-083-funding-accel-refill.md
A5: EXP-084 | B5: v6.71 | C5: 開發期淘汰 | D5: 否 | E5: dev + holdout | F5: 否 | G5: 資金費率7天均值為負時第一段補倉不用等3天，費率過熱時暫停後面幾段補倉 | H5: negative-funding accelerator plus hot-funding brake on later stages (v6.71) | I5: -0.25 | J5: 2/5 | L5: 0.117 | M5: -0.224 | N5: QUAN-968 | O5: EXP-084-funding-accel-brake.md
A6: EXP-086 | B6: v6.73 | C6: 開發期淘汰 | D6: 否 | E6: dev + holdout | F6: 否 | G6: 跌破均線出場後，另一個幣（ETH 池看 BTC）也從低點反彈5%才補倉 | H6: refill stages need the other asset's rebound too (v6.73) | I6: 0 | J6: 2/5 | L6: 0.154 | M6: -0.234 | N6: QUAN-970 | O6: EXP-086-xasset-refill.md
A7: EXP-087 | B7: v6.74 | C7: 開發期淘汰 | D7: 否 | E7: dev + holdout | F7: 否 | G7: 出場後要補倉時，池子近3天成交量須不低於近30天常態才放回 | H7: refill stages only while pool volume confirms the rebound (v6.74) | I7: -2.41 | J7: 1/5 | L7: 0.114 | M7: -0.215 | N7: QUAN-971 | O7: EXP-087-volume-confirmed-refill.md
A8: EXP-088 | B8: v6.75 | C8: 通過（holdout） | D8: 是 | E8: dev + holdout | F8: 是 | G8: 跌破均線出場後分段補倉，但當天盤中創新低就不算數、不補倉 | H8: refill days count only without a new intraday low (v6.75) | I8: 0.47 | J8: 4/5 | K8: 2/2 windows (time-split) | L8: 0.154 | M8: -0.243 | N8: QUAN-972 | O8: EXP-088-no-new-low-refill.md
A9: EXP-090 | B9: v6.77 | C9: 開發期淘汰 | D9: 否 | E9: dev + holdout | F9: 否 | G9: 近7天實際波動高於隱含波動（DVOL）時，部署比例少放一段（減25%） | H9: one refill stage less while realised vol exceeds implied vol (v6.77) | I9: -1.29 | J9: 2/5 | L9: 0.131 | M9: -0.217 | N9: QUAN-974 | O9: EXP-090-vrp-pull.md
A10: EXP-092 | B10: v6.79 | C10: 開發期淘汰 | D10: 否 | E10: dev + holdout | F10: 否 | G10: 鏈上 gas 暴增（超過30天常態3倍）當天與之後兩天，暫停一切補倉 | H10: no refill stage for 3 days after an on-chain gas spike (v6.79) | I10: 0 | J10: 1/5 | L10: 0.139 | M10: -0.23 | N10: QUAN-976 | O10: EXP-092-gas-panic-hold.md
A11: EXP-093 | B11: v6.80 | C11: 開發期淘汰 | D11: 否 | E11: dev + holdout | F11: 否 | G11: 穩定幣總市值比7天前增加時，才允許跌破均線後的分段補倉 | H11: refill stages only while stablecoin supply is growing (v6.80) | I11: -2.08 | J11: 1/5 | L11: 0.127 | M11: -0.24 | N11: QUAN-977 | O11: EXP-093-stable-flow-refill.md
A12: EXP-094 | B12: v6.81 | C12: 開發期淘汰 | D12: 否 | E12: dev + holdout | F12: 否 | G12: 週六、週日的收盤不觸發補倉，只在平日的收盤把錢分段放回 LP | H12: no refill stage on weekend closes (v6.81) | I12: -2.32 | J12: 2/5 | L12: 0.131 | M12: -0.249 | N12: QUAN-978 | O12: EXP-094-no-weekend-refill.md
A13: EXP-096 | B13: v6.83 | C13: 開發期淘汰 | D13: 否 | E13: dev + holdout | F13: 否 | G13: 池內近3天交易者是淨買入幣的一方時，才允許分段補倉 | H13: refill stages only while the pool's traders are net buyers (v6.83) | I13: -1.04 | J13: 0/5 | L13: 0.135 | M13: -0.244 | N13: QUAN-980 | O13: EXP-096-flow-refill.md
A14: EXP-098 | B14: v6.85 | C14: 開發期淘汰 | D14: 否 | E14: dev + holdout | F14: 否 | G14: 補倉要看的「出場後最低點」改用盤中最低價，而不是最低收盤價 | H14: refill measured from the intraday low since the exit (v6.85) | I14: -12.74 | J14: 2/5 | L14: 0.042 | M14: -0.249 | N14: QUAN-982 | O14: EXP-098-low-from-wick.md
A15: EXP-099 | B15: v6.86 | C15: 開發期淘汰 | D15: 否 | E15: dev + holdout | F15: 否 | G15: 補倉那天必須收紅（收盤高於開盤）才算數，否則不補倉也不累計 | H15: refill days must close above their open (v6.86) | I15: -1.42 | J15: 2/5 | L15: 0.158 | M15: -0.233 | N15: QUAN-983 | O15: EXP-099-up-day-refill.md
A16: EXP-100 | B16: v6.87 | C16: 開發期淘汰 | D16: 否 | E16: dev + holdout | F16: 否 | G16: 補倉那天收盤必須落在當日最高到最低區間的上半段才算數 | H16: refill days must close in the upper half of their range (v6.87) | I16: -3.76 | J16: 2/5 | L16: 0.153 | M16: -0.229 | N16: QUAN-984 | O16: EXP-100-strong-close-refill.md
A17: EXP-107 | B17: v6.94 | C17: 開發期淘汰 | D17: 否 | E17: dev + holdout | F17: 否 | G17: 補倉後10天內又被迫出場的話，下次第一段補倉要連6天確認而不是3天 | H17: longer stage-1 wait after a refill that failed fast (v6.94) | I17: -0.36 | J17: 1/5 | L17: 0.113 | M17: -0.25 | N17: QUAN-991 | O17: EXP-107-fail-cooldown.md
A18: EXP-108 | B18: v6.95 | C18: holdout 失敗 | D18: 否 | E18: dev + holdout | F18: 否 | G18: 池內流動性擁擠（7日均值超過90日中位數1.5倍）時，暫停補倉 | H18: no refill stage while pool liquidity is crowded (v6.95) | I18: 0.25 | J18: 3/5 | K18: 0/2 windows (time-split) | L18: 0.16 | M18: -0.228 | N18: QUAN-992 | O18: EXP-108-crowd-refill.md
A19: EXP-109 | B19: v6.96 | C19: holdout 失敗 | D19: 否 | E19: dev + holdout | F19: 是 | G19: 創新低那天不補倉，且池內流動性擁擠（超過常態1.5倍）時也暫停補倉 | H19: crowd-gated refill plus v6.75 (v6.96) | I19: 3.07 | J19: 4/5 | K19: 1/2 windows (time-split) | L19: 0.176 | M19: -0.241 | N19: QUAN-993 | O19: EXP-109-crowd-refill-nolow.md
A20: EXP-144 | B20: v6.130 | C20: 開發期淘汰 | D20: 否 | E20: dev + holdout | F20: 是 | G20: 創新低那天不補倉＋另一個幣（ETH 池看 BTC）也反彈才補倉＋換幣改走較便宜的池子 | H20: v6.75 + cross-asset refill + routing on every pool (v6.130) | I20: 1.04 | J20: 4/5 | L20: 0.169 | M20: -0.247 | N20: QUAN-1029 | O20: EXP-144-nolow-xasset-route.md
A21: EXP-145 | B21: v6.131 | C21: 開發期淘汰 | D21: 否 | E21: dev + holdout | F21: 是 | G21: 創新低不補倉＋另一個幣也反彈才補倉＋換幣走較便宜池子＋部署比例一升就重擺區間 | H21: v6.75 + cross-asset refill + routing + rise rebuild on every pool (v6.131) | I21: 1.94 | J21: 4/5 | L21: 0.178 | M21: -0.245 | N21: QUAN-1030 | O21: EXP-145-nolow-xasset-route-rise.md
A22: EXP-148 | B22: v6.134 | C22: 開發期淘汰 | D22: 否 | E22: dev + holdout | F22: 是 | G22: 創新低不補倉＋另一個幣也反彈才補倉＋換幣走較便宜池子＋FOMC／CPI前後撤區間 | H22: v6.75 + cross-asset refill + routing + macro restore on every pool (v6.134) | I22: 1.15 | J22: 4/5 | L22: 0.171 | M22: -0.249 | N22: QUAN-1033 | O22: EXP-148-nolow-xasset-route-macro.md
A23: EXP-152 | B23: v6.138 | C23: 開發期淘汰 | D23: 否 | E23: dev + holdout | F23: 是 | G23: 創新低不補倉＋成交量確認才補倉＋換幣走較便宜池子＋FOMC／CPI前後撤區間 | H23: v6.75 + routing + macro restore + volume-confirmed refill on every pool (v6.138) | I23: -3.11 | J23: 1/5 | L23: 0.137 | M23: -0.222 | N23: QUAN-1037 | O23: EXP-152-nolow-route-macro-vol.md
A24: EXP-157 | B24: v6.142 | C24: 通過（全歷史） | D24: 是 | E24: 全歷史 | F24: 是 | G24: 跌破均線出場後分段補倉，創新低那天不補倉；改用新基準 spec v1 設定重新評估 | H24: v6.75 (refill days need no new intraday low) re-judged on spec v1 (v6.142) | K24: full-history 5/7 pools (ETH 3 of 5; BTC 2 of 2) | N24: QUAN-1044 | O24: EXP-157-nolow-specv1.md
A25: EXP-158 | B25: v6.143 | C25: 通過（全歷史） | D25: 是 | E25: 全歷史 | F25: 是 | G25: 創新低那天不補倉，且另一個幣（ETH 池看 BTC）也從低點反彈5%才補倉 | H25: v6.75 + cross-asset refill on every pool on spec v1 (v6.143) | K25: full-history 4/7 pools (ETH 3 of 5; BTC 1 of 2) | N25: QUAN-1045 | O25: EXP-158-nolow-xasset-specv1.md
A27: 回補：撤出後分階段買回的條件
A28: 結論：唯一一再成立的發現：v6.75（5/7）；跨資產回補只對 ETH 有用
A29: 綠底 = 通過。ETH 連續 CAGR / 回撤是 registry 記錄的 ETH 連續回測；全歷史判定的逐池數字見各 EXP 文件。

Sheet 重建時機
A1: EXP | B1: 版本 | C1: 狀態 | D1: 通過 | E1: 判定規則 | F1: 含 v6.75 | G1: 說明（中文） | H1: 原始名稱（registry） | I1: 開發期中位數增益（pt） | J1: 開發期勝 | K1: holdout / 全歷史結果 | L1: ETH 連續 CAGR | M1: ETH 連續最大回撤 | N1: Jira | O1: 文件
A2: EXP-023 | B2: v6.18 | C2: 開發期淘汰 | D2: 否 | E2: dev + holdout | F2: 否 | G2: 價格到建倉價 +10% 就重新置中，不等到 +20% 邊緣 | H2: recentre the ladder at +10% from the build price instead of the +20% edge (v6.18) | I2: 0.64 | J2: 4/5 | L2: 0.183 | M2: -0.262 | N2: QUAN-874 | O2: EXP-023-early-upside-recentre.md
A3: EXP-055 | B3: v6.42 | C3: 開發期淘汰 | D3: 否 | E3: dev + holdout | F3: 否 | G3: 部署比例變動時，各段區間在原位置按比例加減流動性，不整個重新擺放 | H3: follow F by resizing every band in place instead of a full rebuild (v6.42) | I3: -5.55 | J3: 2/5 | L3: 0.108 | M3: -0.21 | N3: QUAN-937 | O3: EXP-055-resize-in-place.md
A4: EXP-057 | B4: v6.44 | C4: 開發期淘汰 | D4: 否 | E4: dev + holdout | F4: 否 | G4: 價格跑出區間時直接在現價重新擺放，但不先換幣調整ETH占比 | H4: range-exit rebuild from inventory without the swap (base + limit) (v6.44) | I4: -7.65 | J4: 1/5 | L4: 0.105 | M4: -0.214 | N4: QUAN-939 | O4: EXP-057-swapless-exit.md
A5: EXP-058 | B5: v6.45 | C5: 開發期淘汰 | D5: 否 | E5: dev + holdout | F5: 否 | G5: 部署比例變動時，價格仍在區間中心附近就原地縮放，偏離太遠才整個重擺 | H5: resize in place while the price is in the ladder's inner half; recentre otherwise (v6.45) | I5: 0.92 | J5: 3/5 | L5: 0.135 | M5: -0.224 | N5: QUAN-940 | O5: EXP-058-resize-near-centre.md
A6: EXP-061 | B6: v6.48 | C6: 開發期淘汰 | D6: 否 | E6: dev + holdout | F6: 否 | G6: 部署比例上升就在現價加擺一段新區間，下降就把各段按比例縮小 | H6: F up adds a new tranche at today's price; F down shrinks every band; no recentre on follow events (v6.48) | I6: -0.28 | J6: 2/5 | L6: 0.134 | M6: -0.221 | N6: QUAN-943 | O6: EXP-061-tranche-add.md
A7: EXP-062 | B7: v6.49 | C7: 開發期淘汰 | D7: 否 | E7: dev + holdout | F7: 否 | G7: 部署比例下降時原地按比例縮小區間，上升時才整個重新置中 | H7: asymmetric follow: shrink in place when F falls; v6 recentre when F rises (v6.49) | I7: -0.04 | J7: 2/5 | L7: 0.132 | M7: -0.23 | N7: QUAN-944 | O7: EXP-062-follow-asym.md
A8: EXP-065 | B8: v6.52 | C8: 開發期淘汰 | D8: 否 | E8: dev + holdout | F8: 否 | G8: 除了原本的觸發條件外，每週日再固定把區間整個重新置中一次 | H8: weekly time-based full recentre on top of v6's triggers (v6.52) | I8: -1.95 | J8: 2/5 | L8: 0.171 | M8: -0.239 | N8: QUAN-947 | O8: EXP-065-weekly-recentre.md
A9: EXP-070 | B9: v6.57 | C9: 開發期淘汰 | D9: 否 | E9: dev + holdout | F9: 否 | G9: 每週日固定把區間重新置中一次，且ETH占比不分多空固定50% | H9: weekly recentre + ETH share 50% (stack of EXP-065 and EXP-046) (v6.57) | I9: -2.4 | J9: 1/5 | L9: 0.162 | M9: -0.182 | N9: QUAN-953 | O9: EXP-070-weekly-recentre-share50.md
A10: EXP-071 | B10: v6.58 | C10: 開發期淘汰 | D10: 否 | E10: dev + holdout | F10: 否 | G10: 只在價格高於100日均線時，每週日固定把區間重新置中一次 | H10: weekly recentre only above EMA100 (v6.58) | I10: 0.02 | J10: 3/5 | L10: 0.175 | M10: -0.245 | N10: QUAN-954 | O10: EXP-071-weekly-recentre-uptrend.md
A11: EXP-072 | B11: v6.59 | C11: 開發期淘汰 | D11: 否 | E11: dev + holdout | F11: 否 | G11: 價格低於100日均線時原地縮放區間，高於時才整個重新置中 | H11: follow events below EMA100 resize in place; v6 recentre above (v6.59) | I11: -1.87 | J11: 0/5 | L11: 0.108 | M11: -0.221 | N11: QUAN-955 | O11: EXP-072-resize-below-ema.md
A12: EXP-074 | B12: v6.61 | C12: 開發期淘汰 | D12: 否 | E12: dev + holdout | F12: 否 | G12: 拿掉價格跑出區間後的重新擺放，看這條規則是否真的需要 | H12: no range-exit rebuild (ablation) (v6.61) | I12: -3.56 | J12: 0/5 | L12: 0.114 | M12: -0.17 | N12: QUAN-957 | O12: EXP-074-no-exit-rebuild.md
A13: EXP-075 | B13: v6.62 | C13: 開發期淘汰 | D13: 否 | E13: dev + holdout | F13: 否 | G13: 價格往下跑出區間時不重新擺放，只有往上跑出時才重新置中 | H13: no rebuild after downward range exits (ablation) (v6.62) | I13: 0 | J13: 0/5 | L13: 0.139 | M13: -0.228 | N13: QUAN-958 | O13: EXP-075-no-down-exit-rebuild.md
A14: EXP-135 | B14: v6.121 | C14: 開發期淘汰 | D14: 否 | E14: dev + holdout | F14: 是 | G14: 創新低不補倉＋換幣走較便宜池子＋價格穿越100日均線使ETH占比切換時重擺區間 | H14: v6.75 + routing + rebuild when the ETH share flips on every pool (v6.121) | I14: -0.55 | J14: 2/5 | L14: 0.153 | M14: -0.245 | N14: QUAN-1020 | O14: EXP-135-nolow-route-flip.md
A15: EXP-137 | B15: v6.123 | C15: 通過（holdout） | D15: 是 | E15: dev + holdout | F15: 是 | G15: 創新低那天不補倉＋換幣改走較便宜的池子＋部署比例一上升就重新擺放區間 | H15: v6.75 + routing + rebuild on every F rise on every pool (v6.123) | I15: 1.6 | J15: 4/5 | K15: 2/2 windows (time-split) | L15: 0.164 | M15: -0.245 | N15: QUAN-1021 | O15: EXP-137-nolow-route-rise.md
A16: EXP-142 | B16: v6.128 | C16: 通過（holdout） | D16: 是 | E16: dev + holdout | F16: 是 | G16: 創新低不補倉＋換幣走較便宜池子＋FOMC／CPI前後撤區間＋部署比例一升就重擺 | H16: v6.75 + routing + macro restore + rise rebuild on every pool (v6.128) | I16: 1.73 | J16: 4/5 | K16: 2/2 windows (time-split) | L16: 0.166 | M16: -0.246 | N16: QUAN-1027 | O16: EXP-142-nolow-route-macro-rise.md
A18: 重建時機：什麼時候重建區間、重心放哪裡
A19: 結論：上漲 / 比例翻轉時重建，跨時間不成立；通過的都含 v6.75
A20: 綠底 = 通過。ETH 連續 CAGR / 回撤是 registry 記錄的 ETH 連續回測；全歷史判定的逐池數字見各 EXP 文件。

Sheet 區間寬度形狀
A1: EXP | B1: 版本 | C1: 狀態 | D1: 通過 | E1: 判定規則 | F1: 含 v6.75 | G1: 說明（中文） | H1: 原始名稱（registry） | I1: 開發期中位數增益（pt） | J1: 開發期勝 | K1: holdout / 全歷史結果 | L1: ETH 連續 CAGR | M1: ETH 連續最大回撤 | N1: Jira | O1: 文件
A2: EXP-006 | B2: v6.6 | C2: 開發期淘汰 | D2: 否 | E2: dev + holdout | F2: 否 | G2: 半邊梯子：ETH 那半邊持現貨，只有 USDC 那半邊做 LP | H2: half ladder: base side held as spot; only the quote side LPd (v6.6) | I2: 0.69 | J2: 4/5 | L2: 0.238 | M2: -0.289 | N2: QUAN-840 | O2: EXP-006-half-ladder.md
A3: EXP-007 | B3: v6.7 | C3: 開發期淘汰 | D3: 否 | E3: dev + holdout | F3: 否 | G3: 只在 EMA100 一階、二階差分都 > 0 時用半邊梯子 | H3: half ladder only when EMA100 1st and 2nd differences > 0 (v6.7) | I3: -0.37 | J3: 1/5 | L3: 0.194 | M3: -0.279 | N3: QUAN-841 | O3: EXP-007-half-ladder-when-accelerating.md
A4: EXP-010 | B4: v6.6r | C4: holdout 失敗 | D4: 否 | E4: dev + holdout | F4: 否 | G4: v6.6 半邊梯子改用 Calmar 規則重新判定 | H4: v6.6 half ladder re-registered under a Calmar rule (v6.6r) | I4: 0.69 | J4: 4/5 | K4: 2/4 | L4: 0.238 | M4: -0.289 | N4: QUAN-845 | O4: EXP-010-half-ladder-calmar.md
A5: EXP-013 | B5: v6.10 | C5: 開發期淘汰 | D5: 否 | E5: dev + holdout | F5: 否 | G5: 趨勢偏移區間：谷型往 EMA100 趨勢方向偏 5 pt | H5: trend-skewed range: valley shifted 5 pts toward the EMA100 trend (v6.10) | I5: -0.94 | J5: 1/5 | L5: 0.132 | M5: -0.226 | N5: QUAN-858 | O5: EXP-013-trend-skewed-range.md
A6: EXP-030 | B6: v6.25 | C6: 開發期淘汰 | D6: 否 | E6: dev + holdout | F6: 否 | G6: 梯子半寬 = 30 日 sigma × √30，限 10..30% | H6: ladder half-width = 30-day sigma x sqrt(30), 10..30%, instead of fixed ±20% (v6.25) | I6: -3.66 | J6: 1/5 | L6: 0.137 | M6: -0.199 | N6: QUAN-882 | O6: EXP-030-vol-scaled-width.md
A7: EXP-034 | B7: v6.25 | C7: 通過（holdout） | D7: 是 | E7: dev + holdout | F7: 否 | G7: 波動率調寬（v6.25）單獨判定 | H7: volatility-scaled ladder width (v6.25) judged standalone (v6.25r) | I7: -3.66 | J7: 1/5 | K7: 2/3 pools | L7: 0.137 | M7: -0.199 | N7: QUAN-886 | O7: EXP-034-vol-width-standalone.md
A8: EXP-049 | B8: v6.36 | C8: 通過（holdout） | D8: 是 | E8: dev + holdout | F8: 否 | G8: ETH 50% + 波動率調寬 | H8: ETH share 50% + volatility-scaled ladder width (v6.36) | I8: -2.04 | J8: 1/5 | K8: 2/3 pools (standalone) | L8: 0.136 | M8: -0.169 | N8: QUAN-901 | O8: EXP-049-share50-vol-width.md
A9: EXP-051 | B9: v6.38 | C9: 通過（holdout） | D9: 是 | E9: dev + holdout | F9: 否 | G9: ETH 50% + 兩天確認 + 波動率調寬 | H9: ETH share 50% + exit confirmation + volatility-scaled width (v6.38) | I9: -4.56 | J9: 0/5 | K9: 2/3 pools (standalone) | L9: 0.114 | M9: -0.166 | N9: QUAN-903 | O9: EXP-051-share50-confirm-vol-width.md
A10: EXP-063 | B10: v6.50 | C10: holdout 失敗 | D10: 否 | E10: dev + holdout | F10: 否 | G10: 四條均線帳戶各自擺一段子區間，哪個帳戶狀態變了就只重擺它那一段 | H10: one real sub-ladder per virtual EMA account; each rebuilt only when its account changes state (v6.50) | I10: 1.81 | J10: 3/5 | K10: 1/2 windows (time-split) | L10: 0.146 | M10: -0.237 | N10: QUAN-945 | O10: EXP-063-account-tranches.md
A11: EXP-073 | B11: v6.60 | C11: holdout 失敗 | D11: 否 | E11: dev + holdout | F11: 否 | G11: ETH占比不分多空都固定70%，拿掉依100日均線切換占比看是否需要 | H11: ETH share 70% in both trend states (ablation of the EMA100 share switch) (v6.60) | I11: 3.61 | J11: 4/5 | K11: 1/2 windows (time-split) | L11: 0.171 | M11: -0.247 | N11: QUAN-956 | O11: EXP-073-share-70.md
A12: EXP-153 | B12: v6.139 | C12: 失敗（全歷史） | D12: 否 | E12: 全歷史 | F12: 否 | G12: 價格在100日均線上方時區間全放ETH，只擺現價往上+20%那半邊 | H12: one-sided ETH ladder above EMA100: ETH share 100% while the close is above EMA100 (v6.139) | I12: 1.63 | J12: 3/5 | K12: full-history 1/7 pools (no BTC win) | L12: 0.139 | M12: -0.254 | N12: QUAN-1038 | O12: EXP-153-one-sided-above-ema.md
A13: EXP-154 | B13: v6.140 | C13: 失敗（全歷史） | D13: 否 | E13: 全歷史 | F13: 否 | G13: 價格在100日均線上方時，流動性區間改成上方+40%、下方-20% | H13: asymmetric ladder +40% / -20% while the close is above EMA100 (v6.140) | I13: -0.28 | J13: 2/5 | K13: full-history 3/7 pools (ETH 3 of 4 valid; no BTC win) | L13: 0.173 | M13: -0.246 | N13: QUAN-1039 | O13: EXP-154-wide-top-above-ema.md
A14: EXP-164 | B14: v6.149 | C14: 失敗（全歷史） | D14: 否 | E14: 全歷史 | F14: 是 | G14: 創新低那天不補倉，且價格在100日均線上方時區間改成上+40%、下-20% | H14: v6.75 + +40% / -20% ladder above EMA100 on every pool on spec v1 (v6.149) | K14: full-history 2/7 pools (ETH 2 of 5; BTC 0 of 2) | N14: QUAN-1051 | O14: EXP-164-nolow-widetop-specv1.md
A15: EXP-165 | B15: v6.150 | C15: 失敗（全歷史） | D15: 否 | E15: 全歷史 | F15: 否 | G15: 梯子半寬 = ETH DVOL 一個月預期波動（10..30%） | H15: ladder half-width = ETH DVOL one-month move (10..30%) instead of fixed ±20% on spec v1 (v6.150) | K15: full-history 0/1 pools (ETH/USDC 0x88e6) | L15: 0.112 | M15: -0.248 | N15: QUAN-1071 | O15: EXP-165-width-dvol.md
A16: EXP-166 | B16: v6.151 | C16: 失敗（全歷史） | D16: 否 | E16: 全歷史 | F16: 否 | G16: 梯子半寬 = 0.10 + 0.40 × ER30（效率比，10..30%） | H16: ladder half-width = 0.10 + 0.40 x ER30 (10..30%) instead of fixed ±20%; ETH/USDC spec v1 and WBTC/ETH v6 (v6.151) | K16: full-history 0/2 pools (ETH/USDC 0x88e6; WBTC/ETH 0x4585) | L16: 0.096 | M16: -0.318 | N16: QUAN-1072 | O16: EXP-166-width-er30.md
A17: EXP-167 | B17: v6.152 | C17: 失敗（全歷史） | D17: 否 | E17: 全歷史 | F17: 否 | G17: 梯子半寬 = 0.10 + 0.20 × F（10..30%） | H17: ladder half-width = 0.10 + 0.20 x F (10..30%) instead of fixed ±20%; ETH/USDC spec v1 and WBTC/ETH v6 (v6.152) | K17: full-history 1/2 pools (WBTC/ETH 0x4585 win; ETH/USDC 0x88e6 lose) | L17: 0.103 | M17: -0.245 | N17: QUAN-1073 | O17: EXP-167-width-F.md
A18: EXP-168 | B18: v6.153 | C18: 失敗（全歷史） | D18: 否 | E18: 全歷史 | F18: 否 | G18: 回補期間（0 < F < 1）梯子下緣設在回補低點 | H18: while 0 < F < 1 the ladder's lower edge sits at the refill low (10..30%); ETH/USDC spec v1 and WBTC/ETH v6 (v6.153) | K18: full-history 0/2 pools (ETH/USDC 0x88e6; WBTC/ETH 0x4585) | L18: 0.129 | M18: -0.218 | N18: QUAN-1074 | O18: EXP-168-width-refill-low.md
A19: EXP-169 | B19: v6.154 | C19: 失敗（全歷史） | D19: 否 | E19: 全歷史 | F19: 是 | G19: EXP-168 的下緣 + v6.75 | H19: EXP-168's refill-low lower edge + v6.75 no-new-low refill (v6.154) | K19: full-history stage 1 1/2 (ETH/USDC win; WBTC/ETH lose) | L19: 0.145 | M19: -0.224 | N19: QUAN-1075 | O19: EXP-169-rl-nolow.md
A20: EXP-170 | B20: v6.155 | C20: 失敗（全歷史） | D20: 否 | E20: 全歷史 | F20: 否 | G20: EXP-168 的下緣 + ETH 50% | H20: EXP-168's refill-low lower edge + ETH share fixed at 50% (v6.155) | K20: full-history stage 1 1/2 (WBTC/ETH win; ETH/USDC lose) | L20: 0.132 | M20: -0.18 | N20: QUAN-1076 | O20: EXP-170-rl-share50.md
A21: EXP-171 | B21: v6.156 | C21: 失敗（全歷史） | D21: 否 | E21: 全歷史 | F21: 否 | G21: EXP-168 的下緣 + 取消引擎下緣停損 | H21: EXP-168's refill-low lower edge + no engine lower stop (v6.156) | K21: full-history stage 1 0/2 | L21: 0.061 | M21: -0.481 | N21: QUAN-1077 | O21: EXP-171-rl-nostop.md
A22: EXP-172 | B22: v6.157 | C22: 失敗（全歷史） | D22: 否 | E22: 全歷史 | F22: 是 | G22: EXP-168 的下緣 + v6.75 + ETH 50% | H22: EXP-168's refill-low lower edge + v6.75 + ETH share 50% (v6.157) | K22: full-history stage 1 2/2; stage 2 3/7 pools (ETH 3 of 5; BTC 0 of 2) | L22: 0.139 | M22: -0.187 | N22: QUAN-1078 | O22: EXP-172-rl-nolow-share50.md
A23: EXP-173 | B23: v6.158 | C23: 失敗（全歷史） | D23: 否 | E23: 全歷史 | F23: 是 | G23: v6.75 + F = 1 時上緣延到 +40% | H23: v6.75 + +40% upper reach only while F = 1 (v6.158) | K23: full-history 1/7 pools (ETH 1 of 5; BTC 0 of 2); WBTC/ETH win | L23: 0.168 | M23: -0.262 | N23: QUAN-1079 | O23: EXP-173-nolow-fulltop.md
A24: EXP-174 | B24: v6.159 | C24: 失敗（全歷史） | D24: 否 | E24: 全歷史 | F24: 是 | G24: v6.75 + F = 1 時上緣 +40% + 回補期間下緣在回補低點 | H24: v6.75 + +40% upper reach while F = 1 + refill-low lower edge while refilling (v6.159) | K24: full-history 3/7 pools (ETH 3 of 5; BTC 0 of 2); WBTC/ETH win | L24: 0.162 | M24: -0.251 | N24: QUAN-1080 | O24: EXP-174-nolow-fulltop-rl.md
A26: 區間寬度與形狀：±20% 谷型的寬度、偏移、半邊梯子
A27: 結論：固定 ±20% 保留：5 條動態寬度規則全輸；+40% 上緣回撤較深、輸 BTC
A28: 綠底 = 通過。ETH 連續 CAGR / 回撤是 registry 記錄的 ETH 連續回測；全歷史判定的逐池數字見各 EXP 文件。

Sheet ETH比例s
A1: EXP | B1: 版本 | C1: 狀態 | D1: 通過 | E1: 判定規則 | F1: 含 v6.75 | G1: 說明（中文） | H1: 原始名稱（registry） | I1: 開發期中位數增益（pt） | J1: 開發期勝 | K1: holdout / 全歷史結果 | L1: ETH 連續 CAGR | M1: ETH 連續最大回撤 | N1: Jira | O1: 文件
A2: EXP-029 | B2: v6.24 | C2: 開發期淘汰 | D2: 否 | E2: dev + holdout | F2: 否 | G2: ETH 比例 s 隨收盤價高於幾條 EMA 而變 | H2: ETH value share s moves with the share of EMA spans the close is above (v6.24) | I2: -0.02 | J2: 1/5 | L2: 0.141 | M2: -0.231 | N2: QUAN-881 | O2: EXP-029-share-by-armed.md
A3: EXP-046 | B3: v6.33 | C3: 通過（holdout） | D3: 是 | E3: dev + holdout | F3: 否 | G3: ETH 比例固定 50%（拿掉 EMA100 比例規則） | H3: ETH value share fixed at 50% (ablation of the EMA100 share rule) (v6.33) | I3: -3.29 | J3: 1/5 | K3: 3/3 pools (standalone) | L3: 0.139 | M3: -0.187 | N3: QUAN-898 | O3: EXP-046-share-50.md
A5: ETH 比例 s：LP 裡 ETH 佔 70% / 50% 的規則
A6: 結論：固定 50% 單獨表現一樣好：EMA100 比例規則貢獻小
A7: 綠底 = 通過。ETH 連續 CAGR / 回撤是 registry 記錄的 ETH 連續回測；全歷史判定的逐池數字見各 EXP 文件。

Sheet 總經事件
A1: EXP | B1: 版本 | C1: 狀態 | D1: 通過 | E1: 判定規則 | F1: 含 v6.75 | G1: 說明（中文） | H1: 原始名稱（registry） | I1: 開發期中位數增益（pt） | J1: 開發期勝 | K1: holdout / 全歷史結果 | L1: ETH 連續 CAGR | M1: ETH 連續最大回撤 | N1: Jira | O1: 文件
A2: EXP-059 | B2: v6.46 | C2: 開發期淘汰 | D2: 否 | E2: dev + holdout | F2: 否 | G2: FOMC／CPI公布前30分鐘撤下區間，2小時後用撤出的幣原位放回 | H2: pull the ladder 30 min before to 2 h after scheduled FOMC / CPI releases (v6.46) | I2: 0.13 | J2: 3/5 | L2: 0.158 | M2: -0.221 | N2: QUAN-941 | O2: EXP-059-macro-event-pause.md
A3: EXP-060 | B3: v6.47 | C3: holdout 失敗 | D3: 否 | E3: dev + holdout | F3: 否 | G3: FOMC／CPI公布前30分鐘撤下區間，2小時後先換幣再照原樣精確放回 | H3: FOMC / CPI pause with an exact restore of every band's liquidity (v6.47) | I3: 0.11 | J3: 4/5 | K3: 1/2 windows (time-split) | L3: 0.142 | M3: -0.23 | N3: QUAN-942 | O3: EXP-060-macro-pause-restore.md
A4: EXP-122 | B4: v6.109 | C4: 通過（holdout） | D4: 是 | E4: dev + holdout | F4: 是 | G4: 創新低那天不補倉，加上FOMC／CPI公布前後暫撤區間、之後照原樣放回 | H4: v6.75 plus macro pause with exact restore on every pool (v6.109) | I4: 0.58 | J4: 4/5 | K4: 2/2 windows (time-split) | L4: 0.156 | M4: -0.244 | N4: QUAN-1007 | O4: EXP-122-nolow-macro.md
A5: EXP-126 | B5: v6.113 | C5: 通過（holdout） | D5: 是 | E5: dev + holdout | F5: 是 | G5: 創新低不補倉＋FOMC／CPI前後暫撤區間再原樣放回＋換幣改走較便宜的池子 | H5: v6.75 + macro restore + cheapest-tier routing on every pool (v6.113) | I5: 0.58 | J5: 4/5 | K5: 2/2 windows (time-split) | L5: 0.156 | M5: -0.244 | N5: QUAN-1011 | O5: EXP-126-nolow-macro-route.md
A6: EXP-159 | B6: v6.144 | C6: 通過（全歷史） | D6: 是 | E6: 全歷史 | F6: 是 | G6: 創新低不補倉＋另一個幣也反彈才補倉＋FOMC／CPI前後暫撤區間再原樣放回 | H6: v6.75 + cross-asset refill + macro restore on every pool on spec v1 (v6.144) | K6: full-history 4/7 pools (ETH 3 of 5; BTC 1 of 2) | N6: QUAN-1046 | O6: EXP-159-nolow-xasset-macro-specv1.md
A7: EXP-160 | B7: v6.145 | C7: 通過（全歷史） | D7: 是 | E7: 全歷史 | F7: 是 | G7: 創新低那天不補倉，FOMC／CPI公布前後暫撤區間再原樣放回（新基準 spec v1） | H7: v6.75 + macro restore on every pool on spec v1 (v6.145) | K7: full-history 5/7 pools (ETH 3 of 5; BTC 2 of 2) | N7: QUAN-1047 | O7: EXP-160-nolow-macro-specv1.md
A9: 總經事件：CPI / FOMC 等事件前後撤出或恢復
A10: 結論：ETH +0.4 pt CAGR，但重建次數翻倍（gas 未計）
A11: 綠底 = 通過。ETH 連續 CAGR / 回撤是 registry 記錄的 ETH 連續回測；全歷史判定的逐池數字見各 EXP 文件。

Sheet 費率分層組合
A1: EXP | B1: 版本 | C1: 狀態 | D1: 通過 | E1: 判定規則 | F1: 含 v6.75 | G1: 說明（中文） | H1: 原始名稱（registry） | I1: 開發期中位數增益（pt） | J1: 開發期勝 | K1: holdout / 全歷史結果 | L1: ETH 連續 CAGR | M1: ETH 連續最大回撤 | N1: Jira | O1: 文件
A2: EXP-102 | B2: v6.89 | C2: 開發期淘汰 | D2: 否 | E2: dev + holdout | F2: 否 | G2: 高費池：補倉起算低點改用盤中最低價；低費池：當天收紅才補倉 | H2: refill pace by fee tier: wick-anchored on 0.3% and up-day on 0.05% (v6.89) | I2: -1.42 | J2: 2/5 | L2: 0.158 | M2: -0.233 | N2: QUAN-986 | O2: EXP-102-tier-pace.md
A3: EXP-103 | B3: v6.90 | C3: 通過（holdout） | D3: 是 | E3: dev + holdout | F3: 是 | G3: 高費池：盤中一跌破就觸發下方停損；低費池：創新低那天不補倉 | H3: fee tier: intraday stop on 0.3% and no-new-low refill on 0.05% (v6.90) | I3: 0.47 | J3: 4/5 | K3: 2/2 windows (time-split) | L3: 0.154 | M3: -0.243 | N3: QUAN-987 | O3: EXP-103-tier-stop-nolow.md
A4: EXP-104 | B4: v6.91 | C4: 通過（holdout） | D4: 是 | E4: dev + holdout | F4: 是 | G4: 高費池：成交量確認才補倉；低費池：創新低那天不補倉 | H4: fee tier: volume-confirmed refill on 0.3% and no-new-low refill on 0.05% (v6.91) | I4: 0.47 | J4: 4/5 | K4: 2/2 windows (time-split) | L4: 0.154 | M4: -0.243 | N4: QUAN-988 | O4: EXP-104-tier-vol-nolow.md
A5: EXP-110 | B5: v6.97 | C5: holdout 失敗 | D5: 否 | E5: dev + holdout | F5: 是 | G5: 高費池：補倉起算低點改用盤中最低價；低費池：創新低那天不補倉 | H5: fee tier: wick-anchored refill on 0.3% and no-new-low refill on 0.05% (v6.97) | I5: 0.47 | J5: 4/5 | K5: 1/2 windows (time-split) | L5: 0.154 | M5: -0.243 | N5: QUAN-994 | O5: EXP-110-tier-wick-nolow.md
A6: EXP-111 | B6: v6.98 | C6: 開發期淘汰 | D6: 否 | E6: dev + holdout | F6: 是 | G6: 高費池：成交量確認才補倉；低費池：創新低那天不補倉＋跑出區間連兩天才重擺 | H6: fee tier: volume refill on 0.3% and v6.75 + exit confirmation on 0.05% (v6.98) | I6: -2.42 | J6: 2/5 | L6: 0.172 | M6: -0.212 | N6: QUAN-995 | O6: EXP-111-tier-vol-nolowconfirm.md
A7: EXP-112 | B7: v6.99 | C7: 通過（holdout） | D7: 是 | E7: dev + holdout | F7: 是 | G7: 高費池：盤中跌破就停損＋成交量確認才補倉；低費池：創新低那天不補倉 | H7: fee tier: intraday stop + volume refill on 0.3% and v6.75 on 0.05% (v6.99) | I7: 0.47 | J7: 4/5 | K7: 2/2 windows (time-split) | L7: 0.154 | M7: -0.243 | N7: QUAN-997 | O7: EXP-112-tier-stopvol-nolow.md
A8: EXP-113 | B8: v6.100 | C8: 開發期淘汰 | D8: 否 | E8: dev + holdout | F8: 是 | G8: 高費池：成交量確認才補倉；低費池：創新低那天不補倉＋ETH占比固定70% | H8: fee tier: volume refill on 0.3% and v6.75 + ETH share 70% on 0.05% (v6.100) | I8: 5.37 | J8: 4/5 | L8: 0.186 | M8: -0.261 | N8: QUAN-998 | O8: EXP-113-tier-vol-nolow70.md
A9: EXP-114 | B9: v6.101 | C9: 通過（holdout） | D9: 是 | E9: dev + holdout | F9: 是 | G9: 高費池：拿掉下方停損＋成交量確認才補倉；低費池：創新低那天不補倉 | H9: fee tier: no lower stop + volume refill on 0.3% and v6.75 on 0.05% (v6.101) | I9: 0.47 | J9: 4/5 | K9: 2/2 windows (time-split) | L9: 0.154 | M9: -0.243 | N9: QUAN-999 | O9: EXP-114-tier-nostopvol-nolow.md
A10: EXP-115 | B10: v6.102 | C10: 通過（holdout） | D10: 是 | E10: dev + holdout | F10: 是 | G10: 高費池：盤中跌破就停損＋四條均線各擺一段區間；低費池：創新低那天不補倉 | H10: fee tier: account tranches + intraday stop on 0.3% and v6.75 on 0.05% (v6.102) | I10: 0.47 | J10: 4/5 | K10: 2/2 windows (time-split) | L10: 0.154 | M10: -0.243 | N10: QUAN-1000 | O10: EXP-115-tier-tranchestop-nolow.md
A11: EXP-116 | B11: v6.103 | C11: 開發期淘汰 | D11: 否 | E11: dev + holdout | F11: 是 | G11: 高費池：盤中跌破就停損；低費池：創新低那天不補倉＋ETH占比固定70% | H11: fee tier: intraday stop on 0.3% and v6.75 + ETH share 70% on 0.05% (v6.103) | I11: 5.37 | J11: 4/5 | L11: 0.186 | M11: -0.261 | N11: QUAN-1001 | O11: EXP-116-tier-stop-nolow70.md
A12: EXP-118 | B12: v6.105 | C12: 通過（holdout） | D12: 是 | E12: dev + holdout | F12: 是 | G12: 高費池：成交量確認才補倉＋四條均線各擺一段區間；低費池：創新低那天不補倉 | H12: fee tier: account tranches + volume refill on 0.3% and v6.75 on 0.05% (v6.105) | I12: 0.47 | J12: 4/5 | K12: 2/2 windows (time-split) | L12: 0.154 | M12: -0.243 | N12: QUAN-1003 | O12: EXP-118-tier-tranchevol-nolow.md
A13: EXP-119 | B13: v6.106 | C13: 通過（holdout） | D13: 是 | E13: dev + holdout | F13: 是 | G13: 高費池：拿掉下方停損＋四條均線各擺一段區間；低費池：創新低那天不補倉 | H13: fee tier: no lower stop + account tranches on 0.3% and v6.75 on 0.05% (v6.106) | I13: 0.47 | J13: 4/5 | K13: 2/2 windows (time-split) | L13: 0.154 | M13: -0.243 | N13: QUAN-1004 | O13: EXP-119-tier-nostoptranche-nolow.md
A14: EXP-120 | B14: v6.107 | C14: 通過（holdout） | D14: 是 | E14: dev + holdout | F14: 是 | G14: 高費池：盤中停損＋量確認才補倉；低費池：創新低不補倉＋FOMC／CPI前後撤區間 | H14: fee tier: intraday stop + volume refill on 0.3% and v6.75 + macro restore on 0.05% (v6.107) | I14: 0.58 | J14: 4/5 | K14: 2/2 windows (time-split) | L14: 0.156 | M14: -0.244 | N14: QUAN-1005 | O14: EXP-120-tier-stopvol-nolowmacro.md
A15: EXP-121 | B15: v6.108 | C15: 通過（holdout） | D15: 是 | E15: dev + holdout | F15: 是 | G15: 高費池：盤中停損＋量確認補倉＋四條均線各擺一段區間；低費池：創新低不補倉 | H15: fee tier: intraday stop + volume refill + tranches on 0.3% and v6.75 on 0.05% (v6.108) | I15: 0.47 | J15: 4/5 | K15: 2/2 windows (time-split) | L15: 0.154 | M15: -0.243 | N15: QUAN-1006 | O15: EXP-121-tier-stopvoltranche-nolow.md
A16: EXP-124 | B16: v6.111 | C16: 通過（holdout） | D16: 是 | E16: dev + holdout | F16: 是 | G16: 高費池：盤中停損＋量確認補倉＋換幣走較便宜池子；低費池：創新低那天不補倉 | H16: fee tier: stop + volume + routing on 0.3% and v6.75 on 0.05% (v6.111) | I16: 0.47 | J16: 4/5 | K16: 2/2 windows (time-split) | L16: 0.154 | M16: -0.243 | N16: QUAN-1009 | O16: EXP-124-tier-svroute-nolow.md
A17: EXP-125 | B17: v6.112 | C17: 通過（holdout） | D17: 是 | E17: dev + holdout | F17: 是 | G17: 高費池：拿掉下方停損＋換幣改走較便宜的池子；低費池：創新低那天不補倉 | H17: fee tier: no lower stop + routing on 0.3% and v6.75 on 0.05% (v6.112) | I17: 0.47 | J17: 4/5 | K17: 2/2 windows (time-split) | L17: 0.154 | M17: -0.243 | N17: QUAN-1010 | O17: EXP-125-tier-nostoproute-nolow.md
A18: EXP-127 | B18: v6.114 | C18: 開發期淘汰 | D18: 否 | E18: dev + holdout | F18: 是 | G18: 高費池：盤中停損＋量確認補倉＋換幣走便宜池；低費池：創新低不補倉＋收紅才補 | H18: fee tier: stop + volume + routing on 0.3% and v6.75 + up-day refill on 0.05% (v6.114) | I18: -2.76 | J18: 1/5 | L18: 0.153 | M18: -0.232 | N18: QUAN-1012 | O18: EXP-127-tier-svroute-nolowupday.md
A19: EXP-129 | B19: v6.115 | C19: 開發期淘汰 | D19: 否 | E19: dev + holdout | F19: 是 | G19: 高費池：盤中停損＋量確認補倉＋換幣走便宜池；低費池：創新低不補倉＋部署比例不超過兩幣平均 | H19: fee tier: stop + volume + routing on 0.3% and v6.75 + breadth cap on 0.05% (v6.115) | I19: -2.28 | J19: 2/5 | L19: 0.151 | M19: -0.222 | N19: QUAN-1014 | O19: EXP-129-tier-svr-nolowbreadth.md
A20: EXP-130 | B20: v6.116 | C20: 通過（holdout） | D20: 是 | E20: dev + holdout | F20: 是 | G20: 高費池：盤中停損＋量確認補倉＋換幣走便宜池；低費池：創新低不補倉＋另一個幣也反彈才補 | H20: fee tier: stop + volume + routing on 0.3% and v6.75 + cross-asset refill on 0.05% (v6.116) | I20: 1.04 | J20: 4/5 | K20: 2/2 windows (time-split) | L20: 0.169 | M20: -0.247 | N20: QUAN-1015 | O20: EXP-130-tier-svr-nolowxasset.md
A21: EXP-131 | B21: v6.117 | C21: holdout 失敗 | D21: 否 | E21: dev + holdout | F21: 是 | G21: 高費池：盤中停損＋量確認補倉＋換幣走便宜池；低費池：創新低不補倉＋資金費率過熱時部署上限50% | H21: fee tier: stop + volume + routing on 0.3% and v6.75 + funding cap on 0.05% (v6.117) | I21: 0.47 | J21: 4/5 | K21: 1/2 windows (time-split) | L21: 0.164 | M21: -0.209 | N21: QUAN-1016 | O21: EXP-131-tier-svr-nolowfundcap.md
A22: EXP-132 | B22: v6.118 | C22: 開發期淘汰 | D22: 否 | E22: dev + holdout | F22: 是 | G22: 高費池：盤中停損＋量確認補倉＋換幣走便宜池；低費池：創新低不補倉＋收在當日上半段才補 | H22: fee tier: stop + volume + routing on 0.3% and v6.75 + strong-close refill on 0.05% (v6.118) | I22: -3.76 | J22: 2/5 | L22: 0.144 | M22: -0.22 | N22: QUAN-1017 | O22: EXP-132-tier-svr-nolowstrong.md
A23: EXP-134 | B23: v6.120 | C23: 通過（holdout） | D23: 是 | E23: dev + holdout | F23: 是 | G23: 高費池：盤中停損＋量確認補倉＋換幣走便宜池；低費池：創新低不補倉＋部署比例一升就重擺 | H23: fee tier: stop + volume + routing on 0.3% and v6.75 + rebuild on every F rise on 0.05% (v6.120) | I23: 1.6 | J23: 4/5 | K23: 2/2 windows (time-split) | L23: 0.164 | M23: -0.245 | N23: QUAN-1019 | O23: EXP-134-tier-svr-nolowrise.md
A24: EXP-136 | B24: v6.122 | C24: 開發期淘汰 | D24: 否 | E24: dev + holdout | F24: 是 | G24: 高費池：盤中停損＋量確認補倉＋換幣走便宜池；低費池：創新低不補倉＋ETH占比切換就重擺 | H24: fee tier: stop + volume + routing on 0.3% and v6.75 + share-flip rebuild on 0.05% (v6.122) | I24: -0.55 | J24: 2/5 | L24: 0.153 | M24: -0.245 | N24: QUAN-1023 | O24: EXP-136-tier-svr-nolowflip.md
A25: EXP-138 | B25: v6.124 | C25: 通過（holdout） | D25: 是 | E25: dev + holdout | F25: 是 | G25: 高費池：盤中停損＋量確認補倉＋換幣走便宜池；低費池：創新低不補倉＋部署升或占比切換就重擺 | H25: fee tier: stop + volume + routing on 0.3% and v6.75 + rise and share-flip rebuilds on 0.05% (v6.124) | I25: 0.6 | J25: 3/5 | K25: 2/2 windows (time-split) | L25: 0.158 | M25: -0.247 | N25: QUAN-1022 | O25: EXP-138-tier-svr-nolowriseflip.md
A26: EXP-139 | B26: v6.125 | C26: 通過（holdout） | D26: 是 | E26: dev + holdout | F26: 是 | G26: 高費池：盤中停損＋量確認補倉＋換幣走便宜池；低費池：不創新低且另一個幣反彈才補＋部署升就重擺 | H26: fee tier: stop + volume + routing on 0.3% and v6.75 + cross-asset refill + rise rebuild on 0.05% (v6.125) | I26: 1.94 | J26: 4/5 | K26: 2/2 windows (time-split) | L26: 0.178 | M26: -0.245 | N26: QUAN-1024 | O26: EXP-139-tier-svr-nlxrise.md
A27: EXP-140 | B27: v6.126 | C27: 通過（holdout） | D27: 是 | E27: dev + holdout | F27: 是 | G27: 高費池：盤中停損＋量確認＋走便宜池；低費池：不創新低且另一個幣反彈才補＋FOMC／CPI撤區間 | H27: fee tier: stop + volume + routing on 0.3% and v6.75 + cross-asset refill + macro restore on 0.05% (v6.126) | I27: 1.15 | J27: 4/5 | K27: 2/2 windows (time-split) | L27: 0.171 | M27: -0.249 | N27: QUAN-1025 | O27: EXP-140-tier-svr-nlxmacro.md
A28: EXP-141 | B28: v6.127 | C28: 通過（holdout） | D28: 是 | E28: dev + holdout | F28: 是 | G28: 高費池：盤中停損＋量確認＋走便宜池＋部署升就重擺；低費池：不創新低且另一個幣反彈才補倉 | H28: fee tier: stop + volume + routing + rise rebuild on 0.3% and v6.75 + cross-asset refill on 0.05% (v6.127) | I28: 1.04 | J28: 4/5 | K28: 2/2 windows (time-split) | L28: 0.169 | M28: -0.247 | N28: QUAN-1026 | O28: EXP-141-tier-svrrise-nlx.md
A29: EXP-143 | B29: v6.129 | C29: 開發期淘汰 | D29: 否 | E29: dev + holdout | F29: 是 | G29: 高費池：盤中停損＋量確認＋走便宜池；低費池：不創新低且另一個幣反彈才補＋跑出區間連兩天才重擺 | H29: fee tier: stop + volume + routing on 0.3% and v6.75 + cross-asset refill + two-day exit confirmation on 0.05% (v6.129) | I29: -3.32 | J29: 2/5 | L29: 0.184 | M29: -0.217 | N29: QUAN-1028 | O29: EXP-143-tier-svr-nlxconfirm.md
A30: EXP-146 | B30: v6.132 | C30: holdout 失敗 | D30: 否 | E30: dev + holdout | F30: 是 | G30: 兩種池都要另一個幣也反彈才補倉；高費池另加盤中停損＋量確認＋走便宜池，低費池另加創新低不補 | H30: fee tier: stop + volume + routing + cross-asset refill on 0.3% and v6.75 + cross-asset refill on 0.05% (v6.132) | I30: 1.04 | J30: 4/5 | K30: 1/2 windows (time-split) | L30: 0.169 | M30: -0.247 | N30: QUAN-1031 | O30: EXP-146-tier-svrx-nlx.md
A31: EXP-147 | B31: v6.133 | C31: 通過（holdout） | D31: 是 | E31: dev + holdout | F31: 是 | G31: 高費池：盤中停損＋量確認＋走便宜池；低費池：不新低且另一個幣反彈才補＋部署升重擺＋避FOMC／CPI | H31: fee tier: stop + volume + routing on 0.3% and v6.75 + cross-asset refill + rise rebuild + macro restore on 0.05% (v6.133) | I31: 3.17 | J31: 4/5 | K31: 2/2 windows (time-split) | L31: 0.18 | M31: -0.246 | N31: QUAN-1032 | O31: EXP-147-tier-svr-nlxrisemacro.md
A32: EXP-149 | B32: v6.135 | C32: 通過（holdout） | D32: 是 | E32: dev + holdout | F32: 是 | G32: 兩種池都避開FOMC／CPI；高費池加盤中停損＋量確認＋走便宜池，低費池加不創新低且另一個幣反彈才補 | H32: fee tier: stop + volume + routing + macro restore on 0.3% and v6.75 + cross-asset refill + macro restore on 0.05% (v6.135) | I32: 1.15 | J32: 4/5 | K32: 2/2 windows (time-split) | L32: 0.171 | M32: -0.249 | N32: QUAN-1034 | O32: EXP-149-tier-svrmacro-nlxmacro.md
A33: EXP-150 | B33: v6.136 | C33: 通過（holdout） | D33: 是 | E33: dev + holdout | F33: 是 | G33: 兩種池都創新低不補；高費池加盤中停損＋量確認＋走便宜池，低費池加另一個幣反彈才補＋避FOMC／CPI | H33: fee tier: stop + volume + routing + no-new-low refill on 0.3% and v6.75 + cross-asset refill + macro restore on 0.05% (v6.136) | I33: 1.15 | J33: 4/5 | K33: 2/2 windows (time-split) | L33: 0.171 | M33: -0.249 | N33: QUAN-1035 | O33: EXP-150-tier-svrnolow-nlxmacro.md
A34: EXP-151 | B34: v6.137 | C34: 通過（holdout） | D34: 是 | E34: dev + holdout | F34: 是 | G34: 高費池：盤中停損＋量確認＋走便宜池；低費池：不新低且另一個幣反彈才補＋避FOMC／CPI＋均線分段擺 | H34: fee tier: stop + volume + routing on 0.3% and v6.75 + cross-asset refill + macro restore + account tranches on 0.05% (v6.137) | I34: 3.12 | J34: 3/5 | K34: 2/2 windows (time-split) | L34: 0.178 | M34: -0.252 | N34: QUAN-1036 | O34: EXP-151-tier-svr-nlxmacrotranche.md
A35: EXP-163 | B35: v6.148 | C35: 通過（全歷史） | D35: 是 | E35: 全歷史 | F35: 是 | G35: 高費池：創新低那天不補倉；低費池：不創新低且另一個幣也反彈才補倉＋FOMC／CPI前後撤區間 | H35: fee tier: v6.75 on 0.3% pools; v6.75 + cross-asset refill + macro restore on cheaper pools on spec v1 (v6.148) | K35: full-history 5/7 pools (ETH 3 of 5; BTC 2 of 2) | N35: QUAN-1050 | O35: EXP-163-tier-nolow-nlxmacro-specv1.md
A36: EXP-175 | B36: v6.160 | C36: 通過（全歷史） | D36: 是 | E36: 全歷史 | F36: 是 | G36: 費率分層：0.3% 池用 v6.75 + 回補低點下緣；較便宜的池只用 v6.75 | H36: fee tier: v6.75 + refill-low lower edge on 0.3% pools; v6.75 on cheaper pools (v6.160) | K36: full-history 4/7 pools (ETH 3 of 5; BTC 1 of 2); WBTC/ETH win | L36: 0.151 | M36: -0.235 | N36: QUAN-1081 | O36: EXP-175-tier-rl-nolow.md
A38: 費率分層組合：0.3% 池與 0.05% 池各用一組規則
A39: 結論：23 個通過約等於 4 個發現；0.05% 那側都跑 v6.75
A40: 綠底 = 通過。ETH 連續 CAGR / 回撤是 registry 記錄的 ETH 連續回測；全歷史判定的逐池數字見各 EXP 文件。

Sheet 換匯路由
A1: EXP | B1: 版本 | C1: 狀態 | D1: 通過 | E1: 判定規則 | F1: 含 v6.75 | G1: 說明（中文） | H1: 原始名稱（registry） | I1: 開發期中位數增益（pt） | J1: 開發期勝 | K1: holdout / 全歷史結果 | L1: ETH 連續 CAGR | M1: ETH 連續最大回撤 | N1: Jira | O1: 文件
A2: EXP-117 | B2: v6.104 | C2: 開發期淘汰 | D2: 否 | E2: dev + holdout | F2: 否 | G2: LP擺在高費池，但重擺時的換幣改走較便宜的池子（低費池）以省成本 | H2: LP in the 0.3% fee tier with rebuild swaps routed through the 0.05% tier (v6.104) | I2: -0.43 | J2: 2/5 | L2: 0.15 | M2: -0.189 | N2: QUAN-1002 | O2: EXP-117-lp-03-swap-005.md
A3: EXP-123 | B3: v6.110 | C3: 通過（holdout） | D3: 是 | E3: dev + holdout | F3: 是 | G3: 跌破均線後分段補倉、創新低那天不補倉，且換幣改走較便宜的池子 | H3: v6.75 plus cheapest-tier swap routing on every pool (v6.110) | I3: 0.47 | J3: 4/5 | K3: 2/2 windows (time-split) | L3: 0.154 | M3: -0.243 | N3: QUAN-1008 | O3: EXP-123-nolow-route.md
A4: EXP-128 | B4: v6.104r | C4: 開發完成，待前測 | D4: 否 | E4: dev + holdout | F4: 否 | G4: LP擺在高費池、換幣改走較便宜的池子，單獨在 Base 池和最新資料上重新評估 | H4: v6.104 (0.3% tier ladder + 0.05% swap route) judged standalone on Base and the forward window (v6.104r) | J4: 5/5 positive (EXP-117) | K4: H-a 1/1 (H-b pending) | L4: 0.15 | M4: -0.189 | N4: QUAN-1013 | O4: EXP-128-lp03-swap005-standalone.md
A6: 換匯路由：重建時的 swap 走哪個池
A7: 結論：swap 走 0.05% 池：WBTC 約 +1 pt
A8: 綠底 = 通過。ETH 連續 CAGR / 回撤是 registry 記錄的 ETH 連續回測；全歷史判定的逐池數字見各 EXP 文件。

Sheet 非LP本體
A1: EXP | B1: 版本 | C1: 狀態 | D1: 通過 | E1: 判定規則 | F1: 含 v6.75 | G1: 說明（中文） | H1: 原始名稱（registry） | I1: 開發期中位數增益（pt） | J1: 開發期勝 | K1: holdout / 全歷史結果 | L1: ETH 連續 CAGR | M1: ETH 連續最大回撤 | N1: Jira | O1: 文件
A2: EXP-001 | B2: v6.1 | C2: 開發期淘汰 | D2: 否 | E2: dev + holdout | F2: 否 | G2: 現貨趨勢倉：F × 資產的一半改持現貨 ETH | H2: spot trend sleeve: half of F x equity as spot ETH (v6.1) | I2: 8.54 | J2: 4/5 | L2: 0.261 | M2: -0.336 | N2: QUAN-835 | O2: EXP-001-spot-sleeve.md
A3: EXP-002 | B3: v6.2 | C3: 開發期淘汰 | D3: 否 | E3: dev + holdout | F3: 否 | G3: 現貨倉加 0.80 移動停損 | H3: spot sleeve with a 0.80 trailing stop (v6.2) | I3: 10.67 | J3: 4/5 | L3: 0.246 | M3: -0.324 | N3: QUAN-836 | O3: EXP-002-sleeve-trailing-stop.md
A4: EXP-003 | B4: v6.3 | C4: 開發期淘汰 | D4: 否 | E4: dev + holdout | F4: 否 | G4: 現貨倉的停損高點在重建後保留 | H4: sleeve stop whose high survives rebuilds (v6.3) | I4: 10.67 | J4: 4/5 | L4: 0.246 | M4: -0.324 | N4: QUAN-837 | O4: EXP-003-sleeve-stop-keep-high.md
A5: EXP-004 | B5: v6.4 | C5: 通過（holdout） | D5: 是 | E5: dev + holdout | F5: 否 | G5: 閒置 USDC 賺 Aave 存款利率 | H5: idle USDC earns the Aave supply rate (v6.4) | I5: 1.46 | J5: 5/5 | K5: 3/3 | L5: 0.16 | M5: -0.207 | N5: QUAN-838 | O5: EXP-004-idle-cash-yield.md
A6: EXP-009 | B6: v6.1r | C6: holdout 失敗 | D6: 否 | E6: dev + holdout | F6: 否 | G6: v6.1 現貨倉改用 Calmar 規則重新判定 | H6: v6.1 spot sleeve re-registered under a Calmar rule (v6.1r) | I6: 8.54 | J6: 4/5 | K6: 0/4 | L6: 0.261 | M6: -0.336 | N6: QUAN-844 | O6: EXP-009-spot-sleeve-calmar.md
A7: EXP-014 | B7: v6.11 | C7: 開發期淘汰 | D7: 否 | E7: dev + holdout | F7: 否 | G7: 部分永續對沖：在 Binance 空梯子 ETH delta 的 60% | H7: partial perp delta hedge: short 60% of the ladder ETH delta on Binance USDT-M (v6.11) | I7: -12.85 | J7: 0/5 | L7: 0.047 | M7: -0.11 | N7: QUAN-860 | O7: EXP-014-perp-delta-hedge.md
A8: EXP-018 | B8: v6.14 | C8: holdout 失敗 | D8: 否 | E8: dev + holdout | F8: 否 | G8: 熊市空單：F = 0、低於所有 EMA 且 12 個月報酬 < 0 時，空 0.5 × 資產的永續 | H8: bear-phase short leg: short 0.5 x equity perp while F=0 below all EMAs and 12m return < 0 (v6.14) | I8: 6.47 | J8: 4/5 | K8: 1/2 | L8: 0.28 | M8: -0.234 | N8: QUAN-865 | O8: EXP-018-bear-short-leg.md
A9: EXP-019 | B9: v6.15 | C9: 通過（holdout） | D9: 是 | E9: dev + holdout | F9: 否 | G9: 熊市空單加閒置資金收益（v6.14 + v6.4） | H9: bear-phase short leg plus idle-cash yield (v6.14 + v6.4) on the Base USDC/WETH holdout (v6.15) | I9: 8.72 | J9: 5/5 | K9: 3/3 | L9: 0.301 | M9: -0.213 | N9: QUAN-866 | O9: EXP-019-bear-short-cash.md
A10: EXP-020 | B10: v6.16 | C10: holdout 失敗 | D10: 否 | E10: dev + holdout | F10: 否 | G10: 熊市空單，但 2 sigma 暴跌日不進場；無閒置收益 | H10: bear short leg without entries on 2-sigma crash days; no cash yield (v6.16) | I10: 5.45 | J10: 4/5 | K10: 2/5 | L10: 0.276 | M10: -0.234 | N10: QUAN-871 | O10: EXP-020-bear-short-no-crash-entry.md
A11: EXP-021 | B11: v6.16r | C11: holdout 失敗 | D11: 否 | E11: dev + holdout | F11: 否 | G11: v6.16 在 LINK/WETH、UNI/WETH 新池重新判定 | H11: v6.16 re-judged on fresh deep pools LINK/WETH and UNI/WETH (v6.16r) | K11: 2/5 + 2/5 | N11: QUAN-872 | O11: EXP-021-bear-short-alt-eth-holdout.md
A12: EXP-052 | B12: v6.39 | C12: 通過（holdout） | D12: 是 | E12: dev + holdout | F12: 否 | G12: 沒部署進區間的閒置資金，拿去USDC/USDT穩定幣池做LP賺手續費 | H12: idle reserve LP'd in the Uniswap USDC/USDT pool ±0.1% (v6.39) | I12: 0.71 | J12: 5/5 | K12: 2/2 windows (time-split) | L12: 0.145 | M12: -0.222 | N12: QUAN-933 | O12: EXP-052-stable-lp-reserve.md
A13: EXP-133 | B13: v6.119 | C13: 開發期淘汰 | D13: 否 | E13: dev + holdout | F13: 否 | G13: 沒部署的閒置資金做基差交易（買現貨、空永續合約）賺資金費率 | H13: idle reserve held as a basis trade (spot + short USDT-M perp) earning funding (v6.119) | I13: -0.03 | J13: 2/5 | L13: 0.138 | M13: -0.23 | N13: QUAN-1018 | O13: EXP-133-basis-reserve.md
A15: 非 LP 本體：現貨、永續空單、閒置資金收益（依規則不算改進）
A16: 結論：範圍外：閒置收益不算改進（2026-10-05 裁定），2026-10-01 起只做純 LP
A17: 綠底 = 通過。ETH 連續 CAGR / 回撤是 registry 記錄的 ETH 連續回測；全歷史判定的逐池數字見各 EXP 文件。

Sheet 驗證移植
A1: EXP | B1: 版本 | C1: 狀態 | D1: 通過 | E1: 判定規則 | F1: 含 v6.75 | G1: 說明（中文） | H1: 原始名稱（registry） | I1: 開發期中位數增益（pt） | J1: 開發期勝 | K1: holdout / 全歷史結果 | L1: ETH 連續 CAGR | M1: ETH 連續最大回撤 | N1: Jira | O1: 文件
A2: EXP-008 | B2: v6.8 | C2: 開發完成，待前測 | D2: 否 | E2: dev + holdout | F2: 否 | G2: ETH 與 BTC 各半的 v6 組合 | H2: v6 on ETH and BTC as one 50/50 portfolio (v6.8) | N2: QUAN-842 | O2: EXP-008-eth-btc-portfolio.md
A3: EXP-011 | C3: 通過（holdout） | D3: 是 | E3: dev + holdout | F3: 否 | G3: v6 與 v6.4 在 Base cbBTC 池驗證（上線條件 5） | H3: v6 and v6.4 on the Base cbBTC pool (go-live condition 5) | K3: 2/2 | N3: QUAN-859 | O3: EXP-011-base-cbbtc.md
A4: EXP-015 | B4: v6.12 | C4: 失敗（全歷史） | D4: 否 | E4: dev + holdout | F4: 否 | G4: v6 跑 Base WETH/USDC 0.3%，並估算 0.05% / 0.3% 輪換 | H4: fee tier: v6 on Base WETH/USDC 0.3% and a 0.05%/0.3% rotation estimate (v6.12) | I4: -2.45 | J4: 0/3 | N4: QUAN-861 | O4: EXP-015-fee-tier-rotation.md
A5: EXP-156 | C5: 失敗（全歷史） | D5: 否 | E5: 全歷史 | F5: 否 | G5: 把 EXP-140 的規則改用新基準 spec v1（幣安日收盤、固定0.1%成本）重跑 | H5: spec sheet v1 as the baseline; v6.126 (EXP-140) re-run on spec v1 settings (v6.126 on spec v1) | I5: 0.8 | J5: 3/4 (sheet window yearly) | K5: full-history 3/7 pools (ETH 1 of 5; BTC 2 of 2) | L5: 0.186 | M5: -0.276 | N5: QUAN-1041 | O5: EXP-156-v6126-on-spec-v1.md
A7: 驗證 / 移植：換池子、換基準、組合，不改策略
A8: 結論：不是策略改動
A9: 綠底 = 通過。ETH 連續 CAGR / 回撤是 registry 記錄的 ETH 連續回測；全歷史判定的逐池數字見各 EXP 文件。
